{"uuid": "f4c22a78-9e24-4d32-8509-76887ae13864", "counter": 5, "stdout": "\u001b[0;31mAn exception occurred during task execution. To see the full traceback, use -vvv. The error was: PermissionError: [Errno 1] Operation not permitted: b'/tmp'\u001b[0m\r\n\u001b[0;31mfatal: [Ubuntu-20-CP]: FAILED! => {\"changed\": false, \"module_stderr\": \"Shared connection to 192.168.56.35 closed.\\r\\n\", \"module_stdout\": \"Traceback (most recent call last):\\r\\n  File \\\"/home/devops/.ansible/tmp/ansible-tmp-1646620221.467353-24554-38546822069207/AnsiballZ_file.py\\\", line 107, in <module>\\r\\n    _ansiballz_main()\\r\\n  File \\\"/home/devops/.ansible/tmp/ansible-tmp-1646620221.467353-24554-38546822069207/AnsiballZ_file.py\\\", line 99, in _ansiballz_main\\r\\n    invoke_module(zipped_mod, temp_path, ANSIBALLZ_PARAMS)\\r\\n  File \\\"/home/devops/.ansible/tmp/ansible-tmp-1646620221.467353-24554-38546822069207/AnsiballZ_file.py\\\", line 47, in invoke_module\\r\\n    runpy.run_module(mod_name='ansible.modules.file', init_globals=dict(_module_fqn='ansible.modules.file', _modlib_path=modlib_path),\\r\\n  File \\\"/usr/lib/python3.8/runpy.py\\\", line 207, in run_module\\r\\n    return _run_module_code(code, init_globals, run_name, mod_spec)\\r\\n  File \\\"/usr/lib/python3.8/runpy.py\\\", line 97, in _run_module_code\\r\\n    _run_code(code, mod_globals, init_globals,\\r\\n  File \\\"/usr/lib/python3.8/runpy.py\\\", line 87, in _run_code\\r\\n    exec(code, run_globals)\\r\\n  File \\\"/var/tmp/ansible_ansible.builtin.file_payload_jwkjyhma/ansible_ansible.builtin.file_payload.zip/ansible/modules/file.py\\\", line 972, in <module>\\r\\n  File \\\"/var/tmp/ansible_ansible.builtin.file_payload_jwkjyhma/ansible_ansible.builtin.file_payload.zip/ansible/modules/file.py\\\", line 958, in main\\r\\n  File \\\"/var/tmp/ansible_ansible.builtin.file_payload_jwkjyhma/ansible_ansible.builtin.file_payload.zip/ansible/modules/file.py\\\", line 675, in ensure_directory\\r\\n  File \\\"/var/tmp/ansible_ansible.builtin.file_payload_jwkjyhma/ansible_ansible.builtin.file_payload.zip/ansible/module_utils/basic.py\\\", line 1178, in set_fs_attributes_if_different\\r\\n  File \\\"/var/tmp/ansible_ansible.builtin.file_payload_jwkjyhma/ansible_ansible.builtin.file_payload.zip/ansible/module_utils/basic.py\\\", line 938, in set_mode_if_different\\r\\nPermissionError: [Errno 1] Operation not permitted: b'/tmp'\\r\\n\", \"msg\": \"MODULE FAILURE\\nSee stdout/stderr for the exact error\", \"rc\": 1}\u001b[0m", "start_line": 4, "end_line": 6, "runner_ident": "d6f02011-0b40-4660-be08-c94222cd63c9", "event": "runner_on_failed", "pid": 24550, "created": "2022-03-07T02:30:22.084311", "parent_uuid": "f0189807-d56a-949a-6ba7-000000000008", "event_data": {"playbook": "dir-tmp-permission.yaml", "playbook_uuid": "a0d49d7f-49ee-4fa3-a678-4c6d3ac6f67f", "play": "Ubuntu-20-CP", "play_uuid": "f0189807-d56a-949a-6ba7-000000000006", "play_pattern": "Ubuntu-20-CP", "task": "Change /tmp permission", "task_uuid": "f0189807-d56a-949a-6ba7-000000000008", "task_action": "ansible.builtin.file", "task_args": "", "task_path": "/Users/gini/computing-project/openguard-app/ansible_data/project/dir-tmp-permission.yaml:5", "host": "Ubuntu-20-CP", "remote_addr": "Ubuntu-20-CP", "res": {"module_stdout": "Traceback (most recent call last):\r\n  File \"/home/devops/.ansible/tmp/ansible-tmp-1646620221.467353-24554-38546822069207/AnsiballZ_file.py\", line 107, in <module>\r\n    _ansiballz_main()\r\n  File \"/home/devops/.ansible/tmp/ansible-tmp-1646620221.467353-24554-38546822069207/AnsiballZ_file.py\", line 99, in _ansiballz_main\r\n    invoke_module(zipped_mod, temp_path, ANSIBALLZ_PARAMS)\r\n  File \"/home/devops/.ansible/tmp/ansible-tmp-1646620221.467353-24554-38546822069207/AnsiballZ_file.py\", line 47, in invoke_module\r\n    runpy.run_module(mod_name='ansible.modules.file', init_globals=dict(_module_fqn='ansible.modules.file', _modlib_path=modlib_path),\r\n  File \"/usr/lib/python3.8/runpy.py\", line 207, in run_module\r\n    return _run_module_code(code, init_globals, run_name, mod_spec)\r\n  File \"/usr/lib/python3.8/runpy.py\", line 97, in _run_module_code\r\n    _run_code(code, mod_globals, init_globals,\r\n  File \"/usr/lib/python3.8/runpy.py\", line 87, in _run_code\r\n    exec(code, run_globals)\r\n  File \"/var/tmp/ansible_ansible.builtin.file_payload_jwkjyhma/ansible_ansible.builtin.file_payload.zip/ansible/modules/file.py\", line 972, in <module>\r\n  File \"/var/tmp/ansible_ansible.builtin.file_payload_jwkjyhma/ansible_ansible.builtin.file_payload.zip/ansible/modules/file.py\", line 958, in main\r\n  File \"/var/tmp/ansible_ansible.builtin.file_payload_jwkjyhma/ansible_ansible.builtin.file_payload.zip/ansible/modules/file.py\", line 675, in ensure_directory\r\n  File \"/var/tmp/ansible_ansible.builtin.file_payload_jwkjyhma/ansible_ansible.builtin.file_payload.zip/ansible/module_utils/basic.py\", line 1178, in set_fs_attributes_if_different\r\n  File \"/var/tmp/ansible_ansible.builtin.file_payload_jwkjyhma/ansible_ansible.builtin.file_payload.zip/ansible/module_utils/basic.py\", line 938, in set_mode_if_different\r\nPermissionError: [Errno 1] Operation not permitted: b'/tmp'\r\n", "module_stderr": "Shared connection to 192.168.56.35 closed.\r\n", "exception": "Traceback (most recent call last):\r\n  File \"/home/devops/.ansible/tmp/ansible-tmp-1646620221.467353-24554-38546822069207/AnsiballZ_file.py\", line 107, in <module>\r\n    _ansiballz_main()\r\n  File \"/home/devops/.ansible/tmp/ansible-tmp-1646620221.467353-24554-38546822069207/AnsiballZ_file.py\", line 99, in _ansiballz_main\r\n    invoke_module(zipped_mod, temp_path, ANSIBALLZ_PARAMS)\r\n  File \"/home/devops/.ansible/tmp/ansible-tmp-1646620221.467353-24554-38546822069207/AnsiballZ_file.py\", line 47, in invoke_module\r\n    runpy.run_module(mod_name='ansible.modules.file', init_globals=dict(_module_fqn='ansible.modules.file', _modlib_path=modlib_path),\r\n  File \"/usr/lib/python3.8/runpy.py\", line 207, in run_module\r\n    return _run_module_code(code, init_globals, run_name, mod_spec)\r\n  File \"/usr/lib/python3.8/runpy.py\", line 97, in _run_module_code\r\n    _run_code(code, mod_globals, init_globals,\r\n  File \"/usr/lib/python3.8/runpy.py\", line 87, in _run_code\r\n    exec(code, run_globals)\r\n  File \"/var/tmp/ansible_ansible.builtin.file_payload_jwkjyhma/ansible_ansible.builtin.file_payload.zip/ansible/modules/file.py\", line 972, in <module>\r\n  File \"/var/tmp/ansible_ansible.builtin.file_payload_jwkjyhma/ansible_ansible.builtin.file_payload.zip/ansible/modules/file.py\", line 958, in main\r\n  File \"/var/tmp/ansible_ansible.builtin.file_payload_jwkjyhma/ansible_ansible.builtin.file_payload.zip/ansible/modules/file.py\", line 675, in ensure_directory\r\n  File \"/var/tmp/ansible_ansible.builtin.file_payload_jwkjyhma/ansible_ansible.builtin.file_payload.zip/ansible/module_utils/basic.py\", line 1178, in set_fs_attributes_if_different\r\n  File \"/var/tmp/ansible_ansible.builtin.file_payload_jwkjyhma/ansible_ansible.builtin.file_payload.zip/ansible/module_utils/basic.py\", line 938, in set_mode_if_different\r\nPermissionError: [Errno 1] Operation not permitted: b'/tmp'\r\n", "msg": "MODULE FAILURE\nSee stdout/stderr for the exact error", "rc": 1, "_ansible_no_log": false, "changed": false}, "start": "2022-03-07T02:30:21.401777", "end": "2022-03-07T02:30:22.083802", "duration": 0.682025, "ignore_errors": null, "event_loop": null, "uuid": "f4c22a78-9e24-4d32-8509-76887ae13864"}}